<sdf version="1.7">
  <model name="spring_damper_mesh">
    <static>false</static>
    <link name="mass_x0_y0">
      <pose>0.0 0.0 0 0 0 0</pose>
      <inertial>
        <mass>5.025</mass>
        <inertia>
          <ixx>1e-5</ixx>
          <ixy>0</ixy>
          <ixz>0</ixz>
          <iyy>1e-5</iyy>
          <iyz>0</iyz>
          <izz>1e-5</izz>
        </inertia>
      </inertial>
      <collision name="collision_x0_y0">
        <geometry>
          <sphere>
            <radius>0.03</radius>
          </sphere>
        </geometry>
      </collision>
      <visual name="visual_x0_y0">
        <geometry>
          <sphere>
            <radius>0.03</radius>
          </sphere>
        </geometry>
      </visual>
    </link>
    <link name="mass_x1_y0">
      <pose>0.4 0.0 0 0 0 0</pose>
      <inertial>
        <mass>5.025</mass>
        <inertia>
          <ixx>1e-5</ixx>
          <ixy>0</ixy>
          <ixz>0</ixz>
          <iyy>1e-5</iyy>
          <iyz>0</iyz>
          <izz>1e-5</izz>
        </inertia>
      </inertial>
      <collision name="collision_x1_y0">
        <geometry>
          <sphere>
            <radius>0.03</radius>
          </sphere>
        </geometry>
      </collision>
      <visual name="visual_x1_y0">
        <geometry>
          <sphere>
            <radius>0.03</radius>
          </sphere>
        </geometry>
      </visual>
    </link>
    <link name="mass_x0_y1">
      <pose>0.0 0.4 0 0 0 0</pose>
      <inertial>
        <mass>5.025</mass>
        <inertia>
          <ixx>1e-5</ixx>
          <ixy>0</ixy>
          <ixz>0</ixz>
          <iyy>1e-5</iyy>
          <iyz>0</iyz>
          <izz>1e-5</izz>
        </inertia>
      </inertial>
      <collision name="collision_x0_y1">
        <geometry>
          <sphere>
            <radius>0.03</radius>
          </sphere>
        </geometry>
      </collision>
      <visual name="visual_x0_y1">
        <geometry>
          <sphere>
            <radius>0.03</radius>
          </sphere>
        </geometry>
      </visual>
    </link>
    <link name="mass_x1_y1">
      <pose>0.4 0.4 0 0 0 0</pose>
      <inertial>
        <mass>5.025</mass>
        <inertia>
          <ixx>1e-5</ixx>
          <ixy>0</ixy>
          <ixz>0</ixz>
          <iyy>1e-5</iyy>
          <iyz>0</iyz>
          <izz>1e-5</izz>
        </inertia>
      </inertial>
      <collision name="collision_x1_y1">
        <geometry>
          <sphere>
            <radius>0.03</radius>
          </sphere>
        </geometry>
      </collision>
      <visual name="visual_x1_y1">
        <geometry>
          <sphere>
            <radius>0.03</radius>
          </sphere>
        </geometry>
      </visual>
    </link>
    <joint name="test_joint" type="revolute">
      <parent>mass_x0_y0</parent>
      <child>mass_x1_y0</child>
      <axis>
        <xyz>0 1 0</xyz>
      </axis>
      <pose>-0.2 0 0 0 0 0</pose>
    </joint>
  </model>
</sdf>
